Workbook

Sheet TotalDiagnosedPLHIV
A1: city | B1: year | C1: W | D1: B | E1: H | F1: notes
A2: NYC1 | B2: 2016 | C2: 19895 | D2: 32810 | E2: 32614 | F2: aggregate of bronx, king, newyork, queens, richmond
A3: NYC1 | B3: 2017 | C3: 19638 | D3: 32717 | E3: 32534 | F3: population included is 15-64
A4: NYC1 | B4: 2018 | C4: 19299 | D4: 32596 | E4: 32239 | F4: white = total - black - hispanic
A5: NYC1 | B5: 2019 | C5: 18866 | D5: 32335 | E5: 31839
A6: NYC1 | B6: 2020 | C6: 18244 | D6: 31535 | E6: 30940
A7: NYC1 | B7: 2021 | C7: 17661 | D7: 30797 | E7: 30333 | F7: data transformed from raw atlas plus data
A8: NYC1 | B8: 2022 | C8: 17146 | D8: 30221 | E8: 30035
A9: MIA1 | B9: 2016 | C9: 2736.6313 | D9: 9760.0514 | E9: 10479.317
A10: MIA1 | B10: 2017 | C10: 2657 | D10: 9620 | E10: 10685 | F10: population included is 15-64
A11: MIA1 | B11: 2018 | C11: 2657.7876 | D11: 9426.1814 | E11: 10886.031 | F11: white = total - black - hispanic
A12: MIA1 | B12: 2019 | C12: 2578.8297 | D12: 9215.307 | E12: 11066.863
A13: MIA1 | B13: 2020 | C13: 2557.3735 | D13: 8917.4502 | E13: 11177.176
A14: MIA1 | B14: 2021 | C14: 2544.3523 | D14: 8782.6899 | E14: 11476.958
A15: MIA1 | B15: 2022 | C15: 2489.023 | D15: 8613.1656 | E15: 12093.811
A16: MAR | B16: 2016 | C16: 5505.5328 | D16: 1349.8337 | E16: 2822.6336
A17: MAR | B17: 2017 | C17: 5555.4518 | D17: 1409.9098 | E17: 2945.6384
A18: MAR | B18: 2018 | C18: 5623.7002 | D18: 1508.7752 | E18: 3096.5246
A19: MAR | B19: 2019 | C19: 5702.4267 | D19: 1578.6737 | E19: 3228.8995
A20: MAR | B20: 2020 | C20: 5773.9669 | D20: 1639.455 | E20: 3316.5781
A21: MAR | B21: 2021 | C21: 5778.6678 | D21: 1714.3351 | E21: 3433.9971
A22: MAR | B22: 2022 | C22: 5740.0771 | D22: 1785.7042 | E22: 3587.2188
A23: SFA | B23: 2016 | C23: 9265.2296 | D23: 3151.0647 | E23: 3552.7057
... A141: CLA | B141: 2022 | C141: 3686.3297 | D141: 2526.5755 | E141: 2698.0947
A142: NYC | B142: 2016 | C142: 19894.743 | D142: 32810.025 | E142: 32614.232 | F142: aggregate of bronx, king, newyork, queens, richmond
A143: NYC | B143: 2017 | C143: 19637.744 | D143: 32717.344 | E143: 32533.912 | F143: population included is 15-64
A144: NYC | B144: 2018 | C144: 19299.252 | D144: 32596.356 | E144: 32239.392 | F144: white = total - black - hispanic
A145: NYC | B145: 2019 | C145: 18865.849 | D145: 32335.177 | E145: 31838.974
A146: NYC | B146: 2020 | C146: 18244.482 | D146: 31535.467 | E146: 30940.051
A147: NYC | B147: 2021 | C147: 17660.613 | D147: 30796.62 | E147: 30332.767 | F147: data transformed from raw atlas plus data
A148: NYC | B148: 2022 | C148: 17145.992 | D148: 30220.838 | E148: 30035.17
A149: NJE | B149: 2016 | C149: 2237.1313 | D149: 6272.8982 | E149: 3532.9706
A150: NJE | B150: 2017 | C150: 2207.5882 | D150: 6212.7461 | E150: 3554.6657
A151: NJE | B151: 2018 | C151: 2165.6405 | D151: 6111.9379 | E151: 3527.4216
A152: NJE | B152: 2019 | C152: 2108.2525 | D152: 5967.8452 | E152: 3512.9023
A153: NJE | B153: 2020 | C153: 2033.8826 | D153: 5807.259 | E153: 3458.8585
A154: NJE | B154: 2021 | C154: 2031.0121 | D154: 5613.5032 | E154: 3451.4847
A155: NJE | B155: 2022 | C155: 1804.5468 | D155: 5613.3405 | E155: 3489.1127
A156: MEC | B156: 2016 | C156: 1305.1513 | D156: 3381.8718 | E156: 424.97691
A157: MEC | B157: 2017 | C157: 1298.9279 | D157: 3501.2949 | E157: 465.77718
...

Sheet NewDiagnoses
A1: city | B1: year | C1: M/HET | D1: F/HET | E1: 15-34/MSM | F1: 35-64/MSM | G1: 15-34/MWID | H1: 35-64/MWID | I1: PWID | J1: W | K1: B | L1: H | M1: notes
A2: NYC1 | B2: 2016 | C2: 173.82995 | D2: 346.86251 | E2: 735.49188 | F2: 612.46896 | G2: 29.7383 | H2: 24.764088 | I2: 114.84432 | J2: 461.32378 | K2: 815.5893 | L2: 761.08691 | M2: aggregate of bronx, king, newyork, queens, richmond
A3: NYC1 | B3: 2017 | C3: 165.96193 | D3: 312.86603 | E3: 758.75459 | F3: 568.72781 | G3: 27.813585 | H3: 20.847794 | I3: 108.02826 | J3: 440.87209 | K3: 772.74269 | L3: 749.38523 | M3: population included is 15-64
A4: NYC1 | B4: 2018 | C4: 154.59558 | D4: 280.53443 | E4: 652.22102 | F4: 511.9935 | G4: 35.211268 | H4: 27.640845 | I4: 122.80336 | J4: 327.79794 | K4: 742.62189 | L4: 714.58017 | M4: white = total - black - hispanic
A5: NYC1 | B5: 2019 | C5: 140.16305 | D5: 245.28534 | E5: 649.84174 | F5: 485.19725 | G5: 24.396789 | H5: 18.215596 | I5: 125.90023 | J5: 287.6336 | K5: 725.37901 | L5: 675.98739 | M5: het = total - msm - pwid - mwid
A6: NYC1 | B6: 2020 | C6: 78.906397 | D6: 183.88621 | E6: 601.24572 | F6: 422.67214 | G6: 14.859685 | H6: 10.44627 | I6: 109.98357 | J6: 288.09856 | K6: 603.44969 | L6: 530.45175
A7: NYC1 | B7: 2021 | C7: 128.88232 | D7: 208.59566 | E7: 604.1372 | F7: 443.30887 | G7: 20.754946 | H7: 15.229738 | I7: 103.09126 | J7: 294.68539 | K7: 600.06892 | L7: 629.24569 | M7: sum of risk groups = sum of race groups
A8: NYC1 | B8: 2022 | C8: 152.269 | D8: 234.84273 | E8: 599.11359 | F8: 444.82682 | G8: 13.363128 | H8: 9.9217877 | I8: 108.66294 | J8: 260.9851 | K8: 662.64991 | L8: 639.36499
A9: MIA1 | B9: 2016 | C9: 117.8326 | D9: 203.69511 | E9: 394.21228 | F9: 387.33248 | G9: 7 | H9: 7 | I9: 19 | J9: 110.40409 | K9: 344.77067 | L9: 680.82523 | M9: PART of BMP
A10: MIA1 | B10: 2017 | C10: 113.67496 | D10: 189.75662 | E10: 345.17225 | F10: 315.90909 | G10: 5 | H10: 5 | I10: 19 | J10: 84.656459 | K10: 327.21148 | L10: 582.13206
A11: MIA1 | B11: 2018 | C11: 142.22944 | D11: 172.31644 | E11: 341.89499 | F11: 334.62062 | G11: 6 | H11: 6 | I11: 20 | J11: 121.94702 | K11: 324.22422 | L11: 576.82876
A12: MIA1 | B12: 2019 | C12: 115.88923 | D12: 171.11769 | E12: 308.273 | F12: 347.74283 | G12: 3 | H12: 3 | I12: 15 | J12: 82.95549 | K12: 275.56479 | L12: 605.47972
A13: MIA1 | B13: 2020 | C13: 72.120339 | D13: 101.86998 | E13: 241.3444 | F13: 262.36238 | G13: 2 | H13: 3 | I13: 12 | J13: 66.327801 | K13: 183.60304 | L13: 445.06916
A14: MIA1 | B14: 2021 | C14: 90.304234 | D14: 130.84899 | E14: 287.29839 | F14: 311.05991 | G14: 1 | H14: 1 | I14: 9 | J14: 74.675115 | K14: 263.27765 | L14: 493.04724
A15: MIA1 | B15: 2022 | C15: 120.16184 | D15: 146.44724 | E15: 338.99112 | F15: 359.77493 | G15: 1 | H15: 1 | I15: 8 | J15: 66.411649 | K15: 271.42152 | L15: 637.16683
A16: {=INDEX(notes!$P$2:$P$33, INT((ROW()-ROW($A$16))/COUNTA(A2:A8))+1)} -> MAR | B16: 2016 | C16: 26.28444 | D16: 49.87304 | E16: 197.18504 | F16: 165.05118 | G16: 12.755906 | H16: 10.677165 | I16: 34.173228 | J16: 209.92126 | K16: 101.54331 | L16: 184.53543 | S16: =SUM(E16:H16) -> 385.66929
A17: {=INDEX(notes!$P$2:$P$33, INT((ROW()-ROW($A$16))/COUNTA(A3:A9))+1)} -> MAR | B17: 2017 | C17: 19.548255 | D17: 48.870637 | E17: 198.61396 | F17: 158.14168 | G17: 16.868583 | H17: 13.431211 | I17: 20.525667 | J17: 192.55031 | K17: 89.921971 | L17: 193.52772
A18: {=INDEX(notes!$P$2:$P$33, INT((ROW()-ROW($A$16))/COUNTA(A4:A10))+1)} -> MAR | B18: 2018 | C18: 26.998035 | D18: 49.271414 | E18: 220.30361 | F18: 163.02467 | G18: 15.370019 | H18: 11.373814 | I18: 35.658444 | J18: 219.89374 | K18: 83.203036 | L18: 218.90323
A19: {=INDEX(notes!$P$2:$P$33, INT((ROW()-ROW($A$16))/COUNTA(A5:A11))+1)} -> MAR | B19: 2019 | C19: 20.628931 | D19: 47.704403 | E19: 214.95238 | F19: 142.33333 | G19: 18.793651 | H19: 12.444444 | I19: 35.142857 | J19: 203.04762 | K19: 92.738095 | L19: 196.21429
A20: {=INDEX(notes!$P$2:$P$33, INT((ROW()-ROW($A$16))/COUNTA(A6:A12))+1)} -> MAR | B20: 2020 | C20: 17.811825 | D20: 39.186015 | E20: 202.5162 | F20: 120.79914 | G20: 23.390929 | H20: 13.952484 | I20: 37.343413 | J20: 206.37149 | K20: 73.704104 | L20: 174.92441 | M20: population included is 15-64
A21: {=INDEX(notes!$P$2:$P$33, INT((ROW()-ROW($A$16))/COUNTA(A7:A13))+1)} -> MAR | B21: 2021 | C21: 23.878809 | D21: 46.987333 | E21: 215.43307 | F21: 158.58268 | G21: 20.409449 | H21: 15.023622 | I21: 19.685039 | J21: 196.85039 | K21: 86.614173 | L21: 216.53543 | M21: white = total - black - hispanic
A22: {=INDEX(notes!$P$2:$P$33, INT((ROW()-ROW($A$16))/COUNTA(A8:A14))+1)} -> MAR | B22: 2022 | C22: 23.404858 | D22: 57.448289 | E22: 223.01224 | F22: 192.09965 | G22: 19.59965 | H22: 16.882867 | I22: 31.552448 | J22: 201.14685 | K22: 122.26573 | L22: 240.58741 | M22: het = total - msm - pwid - mwid | S22: =SUM(E22:H22) -> 451.59441
A23: {=INDEX(notes!$P$2:$P$33, INT((ROW()-ROW($A$16))/COUNTA(A9:A15))+1)} -> SFA | B23: 2016 | C23: 24.054941 | D23: 55.399258 | E23: 194.65649 | F23: 173.18702 | G23: 20.763359 | H23: 18.473282 | I23: 27.465649 | J23: 237.38168 | K23: 121.63359 | L23: 154.98473
A24: {=INDEX(notes!$P$2:$P$33, INT((ROW()-ROW($A$16))/COUNTA(A10:A16))+1)} -> SFA | B24: 2017 | C24: 21.362637 | D24: 31.415643 | E24: 149.38914 | F24: 153.59729 | G24: 23.131222 | H24: 23.782805 | I24: 29.321267 | J24: 201.33937 | K24: 111.42081 | L24: 119.23982
A25: {=INDEX(notes!$P$2:$P$33, INT((ROW()-ROW($A$16))/COUNTA(A11:A17))+1)} -> SFA | B25: 2018 | C25: 25.57475 | D25: 31.812494 | E25: 160.48292 | F25: 140.07062 | G25: 19.735763 | H25: 17.225513 | I25: 32.09795 | J25: 152.70843 | K25: 106.99317 | L25: 167.29841
A26: {=INDEX(notes!$P$2:$P$33, INT((ROW()-ROW($A$16))/COUNTA(A12:A18))+1)} -> SFA | B26: 2019 | C26: 28.356566 | D26: 37.081663 | E26: 153.56643 | F26: 144.32401 | G26: 17.118881 | H26: 16.088578 | I26: 22.463869 | J26: 176.78089 | K26: 99.622378 | L26: 142.59674
A27: {=INDEX(notes!$P$2:$P$33, INT((ROW()-ROW($A$16))/COUNTA(A13:A19))+1)} -> SFA | B27: 2020 | C27: 16.057696 | D27: 23.789179 | E27: 126.69375 | F27: 99.753125 | G27: 10.875 | H27: 8.5625 | I27: 25.26875 | J27: 115.65313 | K27: 75.80625 | L27: 119.54063
A28: {=INDEX(notes!$P$2:$P$33, INT((ROW()-ROW($A$16))/COUNTA(A14:A20))+1)} -> SFA | B28: 2021 | C28: 18.766188 | D28: 40.312552 | E28: 111.05512 | F28: 138.8189 | G28: 16.356955 | H28: 20.446194 | I28: 23.244094 | J28: 143.33858 | K28: 86.19685 | L28: 139.46457
A29: {=INDEX(notes!$P$2:$P$33, INT((ROW()-ROW($A$16))/COUNTA(A15:A21))+1)} -> SFA | B29: 2022 | C29: 19.29857 | D29: 40.912968 | E29: 168.85817 | F29: 137.05529 | G29: 12.329327 | H29: 10.007212 | I29: 15.538462 | J29: 134.99038 | K29: 84.490385 | L29: 184.51923
A30: {=INDEX(notes!$P$2:$P$33, INT((ROW()-ROW($A$16))/COUNTA(A16:A22))+1)} -> LOR | B30: 2016 | C30: 80.583644 | D30: 190.7835 | E30: 1347.6964 | F30: 900.91464 | G30: 70.125 | H30: 46.8775 | I30: 116.01929 | J30: 836.71536 | K30: 492.59036 | L30: 1423.6943 | M30: los angeles, orange CA, riverside, san bernardino
A31: {=INDEX(notes!$P$2:$P$33, INT((ROW()-ROW($A$16))/COUNTA(A17:A23))+1)} -> LOR | B31: 2017 | C31: 79.434313 | D31: 166.31559 | E31: 1253.057 | F31: 861.37514 | G31: 58.254628 | H31: 40.045334 | I31: 143.51794 | J31: 871.92066 | K31: 418.75784 | L31: 1311.3215
A32: {=INDEX(notes!$P$2:$P$33, INT((ROW()-ROW($A$16))/COUNTA(A18:A24))+1)} -> LOR | B32: 2018 | C32: 90.529657 | D32: 180.41726 | E32: 1200.1893 | F32: 783.18111 | G32: 61.92623 | H32: 40.409836 | I32: 140.3466 | J32: 772.88095 | K32: 415.19204 | L32: 1308.927
A33: {=INDEX(notes!$P$2:$P$33, INT((ROW()-ROW($A$16))/COUNTA(A19:A25))+1)} -> LOR | B33: 2019 | C33: 89.220417 | D33: 191.18661 | E33: 1065.8364 | F33: 794.68884 | G33: 62.563636 | H33: 46.647521 | I33: 130.85661 | J33: 704.46116 | K33: 402.40868 | L33: 1274.1302
A34: {=INDEX(notes!$P$2:$P$33, INT((ROW()-ROW($A$16))/COUNTA(A20:A26))+1)} -> LOR | B34: 2020 | C34: 71.993644 | D34: 157.60771 | E34: 1029.6653 | F34: 686.97117 | G34: 63.877928 | H34: 42.618018 | I34: 116.26622 | J34: 618.45811 | K34: 350.7527 | L34: 1199.7892 | M34: population included is 15-64
A35: {=INDEX(notes!$P$2:$P$33, INT((ROW()-ROW($A$16))/COUNTA(A21:A27))+1)} -> LOR | B35: 2021 | C35: 94.057356 | D35: 164.29499 | E35: 1050.1946 | F35: 783.7156 | G35: 48.755034 | H35: 36.383809 | I35: 155.59857 | J35: 604.77936 | K35: 429.60864 | L35: 1298.612 | M35: white = total - black - hispanic
A36: {=INDEX(notes!$P$2:$P$33, INT((ROW()-ROW($A$16))/COUNTA(A22:A28))+1)} -> LOR | B36: 2022 | C36: 97.518754 | D36: 194.41637 | E36: 1020.8602 | F36: 842.05687 | G36: 63.670004 | H36: 52.518222 | I36: 166.95955 | J36: 571.17741 | K36: 385.6668 | L36: 1481.1558 | M36: het = total - msm - pwid - mwid
A37: {=INDEX(notes!$P$2:$P$33, INT((ROW()-ROW($A$16))/COUNTA(A23:A29))+1)} -> SAC | B37: 2016 | C37: 12.457439 | D37: 16.609919 | E37: 75.979275 | F37: 60.637306 | G37: 5.388601 | H37: 4.3005181 | I37: 11.626943 | J37: 83.326425 | K37: 44.569948 | L37: 59.103627
A38: {=INDEX(notes!$P$2:$P$33, INT((ROW()-ROW($A$16))/COUNTA(A24:A30))+1)} -> SAC | B38: 2017 | C38: 6.9078309 | D38: 20.03271 | E38: 70.637838 | F38: 56.367568 | G38: 7.4918919 | H38: 5.9783784 | I38: 10.583784 | J38: 73.124324 | K38: 44.259459 | L38: 60.616216
A39: {=INDEX(notes!$P$2:$P$33, INT((ROW()-ROW($A$16))/COUNTA(A25:A31))+1)} -> SAC | B39: 2018 | C39: 10.88764 | D39: 21.775281 | E39: 54.269663 | F39: 56.207865 | G39: 7.0786517 | H39: 7.3314607 | I39: 13.449438 | J39: 69.168539 | K39: 39.38764 | L39: 62.44382
A40: {=INDEX(notes!$P$2:$P$33, INT((ROW()-ROW($A$16))/COUNTA(A26:A32))+1)} -> SAC | B40: 2019 | C40: 8.1213969 | D40: 17.402993 | E40: 52.634146 | F40: 49.463415 | G40: 8.097561 | H40: 7.6097561 | I40: 17.670732 | J40: 71.664634 | K40: 33.378049 | L40: 55.957317
...

Sheet LateDiagnoses
B1: city | C1: year | D1: W | E1: B | F1: H | G1: notes
B2: NYC1 | C2: 2016 | G2: includes bronx, king, newyork, queens (assume richmond)
B3: NYC1 | C3: 2017 | D3: ='Multi-County LateDiagnoses'!C129 -> 0.15073727 | E3: ='Multi-County LateDiagnoses'!D129 -> 0.18168534 | F3: ='Multi-County LateDiagnoses'!E129 -> 0.16768941 | G3: assume it stays the same for 15-64
B4: NYC1 | C4: 2018 | D4: ='Multi-County LateDiagnoses'!C130 -> 0.17549389 | E4: ='Multi-County LateDiagnoses'!D130 -> 0.21243611 | F4: ='Multi-County LateDiagnoses'!E130 -> 0.18030611 | G4: assume NYC includes richmond county
B5: NYC1 | C5: 2019 | D5: ='Multi-County LateDiagnoses'!C131 -> 0.14478567 | E5: ='Multi-County LateDiagnoses'!D131 -> 0.17011664 | F5: ='Multi-County LateDiagnoses'!E131 -> 0.18705625
B6: NYC1 | C6: 2020 | D6: ='Multi-County LateDiagnoses'!C132 -> 0.21619341 | E6: ='Multi-County LateDiagnoses'!D132 -> 0.18382691 | F6: ='Multi-County LateDiagnoses'!E132 -> 0.20342677
B7: NYC1 | C7: 2021 | D7: ='Multi-County LateDiagnoses'!C133 -> 0.16567325 | E7: ='Multi-County LateDiagnoses'!D133 -> 0.18806522 | F7: ='Multi-County LateDiagnoses'!E133 -> 0.2089473
B8: NYC1 | C8: 2022 | D8: ='Multi-County LateDiagnoses'!C134 -> 0.21292912 | E8: ='Multi-County LateDiagnoses'!D134 -> 0.15729949 | F8: ='Multi-County LateDiagnoses'!E134 -> 0.19053129
B9: MIA1 | C9: 2016 | G9: no data for 2016
B10: MIA1 | C10: 2017 | D10: =AVERAGE(D12:D13) -> 0.1035 | E10: =AVERAGE(E12:E13) -> 0.186 | F10: =AVERAGE(F12:F13) -> 0.2005 | G10: average of 2019-2020. no county level data for 2017 and 2018
B11: MIA1 | C11: 2018 | D11: =AVERAGE(D12:D13) -> 0.1035 | E11: =AVERAGE(E12:E13) -> 0.186 | F11: =AVERAGE(F12:F13) -> 0.2005 | G11: average of 2019-2020. no county level data for 2017 and 2018
B12: MIA1 | C12: 2019 | D12: 0.089 | E12: 0.199 | F12: 0.196
B13: MIA1 | C13: 2020 | D13: 0.118 | E13: 0.173 | F13: 0.205
B14: MIA1 | C14: 2021 | D14: 0.167 | E14: 0.165 | F14: 0.188
B15: MIA1 | C15: 2022 | D15: 0.188 | E15: 0.221 | F15: 0.182
B16: MAR | C16: 2016 | G16: no data for 2016
B17: MAR | C17: 2017 | D17: 0.188 | E17: 0.117 | F17: 0.189
B18: MAR | C18: 2018 | D18: 0.262 | E18: 0.196 | F18: 0.229
B19: MAR | C19: 2019 | D19: =(D17+D18+D20)/3 -> 0.222 | E19: =(E17+E18+E20)/3 -> 0.167 | F19: =(F17+F18+F20)/3 -> 0.216 | G19: average of 2017, 2018, 2020
B20: MAR | C20: 2020 | D20: 0.216 | E20: 0.188 | F20: 0.23 | G20: state level data
B21: MAR | C21: 2021 | D21: 0.189 | E21: 0.184 | F21: 0.186
B22: MAR | C22: 2022 | D22: =AVERAGE(D20:D21) -> 0.2025 | E22: =AVERAGE(E20:E21) -> 0.186 | F22: =AVERAGE(F20:F21) -> 0.208 | G22: average of 2020-2021. 2020 uses state-level data but data seems close to other years
B23: SFA | C23: 2016
B24: SFA | C24: 2017 | D24: 0.16954299 | E24: 0.17919457 | F24: 0.20965158
B25: SFA | C25: 2018 | D25: 0.15882916 | E25: 0.13133941 | F25: 0.19927563
B26: SFA | C26: 2019 | D26: 0.16339161 | E26: 0.17937063 | F26: 0.153
B27: SFA | C27: 2020 | D27: 0.22235937 | E27: 0.1487125 | F27: 0.20380625
B28: SFA | C28: 2021 | D28: 0.1724147 | E28: 0.17091864 | F28: 0.18937008
B29: SFA | C29: 2022 | D29: 0.1875 | E29: 0.1425 | F29: 0.174
B30: LOR | C30: 2016 | G30: no data for 2016
B31: LOR | C31: 2017 | D31: 0.204 | E31: 0.18 | F31: 0.233 | G31: using state-level data
B32: LOR | C32: 2018 | D32: 0.184 | E32: 0.191 | F32: 0.217 | G32: using state-level data
B33: LOR | C33: 2019 | D33: 0.205 | E33: 0.15 | F33: 0.223 | G33: using state-level data
B34: LOR | C34: 2020 | D34: 0.216 | E34: 0.188 | F34: 0.23 | G34: using state-level data
B35: LOR | C35: 2021 | D35: 0.205 | E35: 0.202 | F35: 0.239 | G35: using state-level data
B36: LOR | C36: 2022 | D36: 0.205 | E36: 0.165 | F36: 0.228 | G36: using state-level data
B37: SAC | C37: 2016 | G37: no data for 2016
B38: SAC | C38: 2017 | D38: 0.204 | E38: 0.18 | F38: 0.233 | G38: using state-level data
B39: SAC | C39: 2018 | D39: 0.184 | E39: 0.191 | F39: 0.217 | G39: using state-level data
B40: SAC | C40: 2019 | D40: 0.205 | E40: 0.15 | F40: 0.223 | G40: using state-level data
...

Sheet ViralSuppression
A1: city | B1: year | C1: W | D1: B | E1: H | F1: notes
A2: ATL | B2: 2016
A3: ATL | B3: 2017 | C3: 0.70845817 | D3: 0.5776699 | E3: 0.62524366 | F3: Data from AHEAD. Proportion of people virally suppressed among people living with diagnosed HIV. By race strata needed only
A4: ATL | B4: 2018 | C4: 0.70301783 | D4: 0.59102578 | E4: 0.63232601 | F4: assume gen pop percent viral suppressed is the same for 15-64
A5: ATL | B5: 2019 | C5: 0.72536974 | D5: 0.60911148 | E5: 0.63731656 | F5: white = (total numerator - balck numerator -hispanic numerator) / (total denominator - black denominator - hispanic denominator)
A6: ATL | B6: 2020 | C6: 0.69757225 | D6: 0.5955028 | E6: 0.62420886 | F6: denominators are 0-99+ age
A7: ATL | B7: 2021 | C7: 0.71878025 | D7: 0.61654989 | E7: 0.6506422 | F7: if any county strata had missing values, data from the earliest available year was used for the addition
A8: ATL | B8: 2022 | C8: 0.72440746 | D8: 0.62823693 | E8: 0.65125043
A9: BAL | B9: 2016
A10: BAL | B10: 2017 | C10: 0.61069837 | D10: 0.55202027 | E10: 0.60326581
A11: BAL | B11: 2018 | C11: 0.61069837 | D11: 0.58622299 | E11: 0.60326581 | F11: Data from AHEAD. Proportion of people virally suppressed among people living with diagnosed HIV. By race strata needed only
A12: BAL | B12: 2019 | C12: 0.67251462 | D12: 0.62860553 | E12: 0.61756374 | F12: 2017 data same as 2018 due to missing values
A13: BAL | B13: 2020 | C13: 0.62027231 | D13: 0.59027123 | E13: 0.6055245
A14: BAL | B14: 2021 | C14: 0.60987261 | D14: 0.62237365 | E14: 0.66588832
A15: BAL | B15: 2022 | C15: 0.58653846 | D15: 0.61780029 | E15: 0.6324101
A16: BEX | B16: 2016
A17: BEX | B17: 2017 | C17: 0.65342163 | D17: 0.5659204 | E17: 0.6770151 | F17: Data from AHEAD. Proportion of people virally suppressed among people living with diagnosed HIV. By race strata needed only
A18: BEX | B18: 2018 | C18: 0.64086022 | D18: 0.57055961 | E18: 0.67367257 | F18: assume gen pop percent viral suppressed is the same for 15-64
A19: BEX | B19: 2019 | C19: 0.6239521 | D19: 0.53453039 | E19: 0.68815072 | F19: white = (total numerator - balck numerator -hispanic numerator) / (total denominator - black denominator - hispanic denominator)
A20: BEX | B20: 2020 | C20: 0.62638581 | D20: 0.55346651 | E20: 0.65666328 | F20: denominators are 0-99+ age
A21: BEX | B21: 2021 | C21: 0.64545455 | D21: 0.53389831 | E21: 0.63955224 | F21: if any county strata had missing values, data from the earliest available year was used for the addition
A22: BEX | B22: 2022 | C22: 0.67995444 | D22: 0.5719697 | E22: 0.69158654
A23: BMP | B23: 2016
A24: BMP | B24: 2017 | C24: 0.72798635 | D24: 0.55157539 | E24: 0.67721 | F24: Data from AHEAD. Proportion of people virally suppressed among people living with diagnosed HIV. By race strata needed only
A25: BMP | B25: 2018 | C25: 0.74463172 | D25: 0.57290433 | E25: 0.6853597
A26: BMP | B26: 2019 | C26: 0.75117206 | D26: 0.57044954 | E26: 0.67553123
A27: BMP | B27: 2020 | C27: 0.74067878 | D27: 0.56908539 | E27: 0.6721984
A28: BMP | B28: 2021 | C28: 0.75444796 | D28: 0.57172182 | E28: 0.69129652
A29: BMP | B29: 2022 | C29: 0.75984991 | D29: 0.59488021 | E29: 0.69710153
A30: CLA | B30: 2016
A31: CLA | B31: 2017 | C31: 0.66863687 | D31: 0.59492481 | E31: 0.65186916 | F31: Data from AHEAD. Proportion of people virally suppressed among people living with diagnosed HIV. By race strata needed only
A32: CLA | B32: 2018 | C32: 0.66863687 | D32: 0.59492481 | E32: 0.65186916 | F32: assume gen pop percent viral suppressed is the same for 15-64
A33: CLA | B33: 2019 | C33: 0.6076087 | D33: 0.54320988 | E33: 0.60685663 | F33: white = (total numerator - balck numerator -hispanic numerator) / (total denominator - black denominator - hispanic denominator)
A34: CLA | B34: 2020 | C34: 0.66917024 | D34: 0.59740803 | E34: 0.66080402 | F34: denominators are 0-99+ age
A35: CLA | B35: 2021 | C35: 0.65748899 | D35: 0.60517799 | E35: 0.65180723 | F35: if any county strata had missing values, data from the earliest available year was used for the addition
A36: CLA | B36: 2022 | C36: 0.66232316 | D36: 0.59770115 | E36: 0.66717153 | F36: 2017 data same as 2018 due to missing values
A37: COO | B37: 2016
A38: COO | B38: 2017 | C38: 0.58049404 | D38: 0.52707192 | E38: 0.59589455 | F38: Data from AHEAD. Proportion of people virally suppressed among people living with diagnosed HIV. By race strata needed only
A39: COO | B39: 2018 | C39: 0.58049404 | D39: 0.52707192 | E39: 0.59589455 | F39: assume gen pop percent viral suppressed is the same for 15-64
A40: COO | B40: 2019 | C40: 0.62076227 | D40: 0.47157988 | E40: 0.53886719 | F40: white = (total numerator - balck numerator -hispanic numerator) / (total denominator - black denominator - hispanic denominator)
...

Sheet Multi-County LateDiagnoses
A1: city | B1: year | C1: W | D1: B | E1: H | F1: New diagnoses | G1: notes
A2: LA | B2: 2016 | F2: 1933
A3: LA | B3: 2017 | C3: 0.204 | D3: 0.18 | E3: 0.233 | F3: 1801 | G3: No county, use state
A4: LA | B4: 2018 | C4: 0.127 | D4: 0.15 | E4: 0.165 | F4: 1751
A5: LA | B5: 2019 | C5: 0.14 | D5: 0.091 | E5: 0.183 | F5: 1287
A6: LA | B6: 2020 | C6: 0.163 | D6: 0.154 | E6: 0.24 | F6: 1448
A7: LA | B7: 2021 | C7: 0.149 | D7: 0.174 | E7: 0.204 | F7: 1544
A8: LA | B8: 2022 | C8: 0.205 | D8: 0.165 | E8: 0.228 | F8: 1625
A9: OCA | B9: 2016 | F9: 351
A10: OCA | B10: 2017 | C10: 0.204 | D10: 0.18 | E10: 0.233 | F10: 314 | G10: No county, use state
A11: OCA | B11: 2018 | C11: 0.184 | D11: 0.191 | E11: 0.217 | F11: 287
A12: OCA | B12: 2019 | C12: 0.205 | D12: 0.15 | E12: 0.223 | F12: 253
A13: OCA | B13: 2020 | C13: 0.215 | D13: 0.186 | E13: 0.246 | F13: 264
A14: OCA | B14: 2021 | C14: 0.205 | D14: 0.202 | E14: 0.239 | F14: 267
A15: OCA | B15: 2022 | C15: 0.205 | D15: 0.165 | E15: 0.228 | F15: 259
A16: RIV | B16: 2016 | F16: 295
A17: RIV | B17: 2017 | C17: 0.204 | D17: 0.18 | E17: 0.233 | F17: 231 | G17: No county, use state
A18: RIV | B18: 2018 | C18: 0.184 | D18: 0.191 | E18: 0.217 | F18: 263
A19: RIV | B19: 2019 | C19: 0.205 | D19: 0.15 | E19: 0.223 | F19: 283
A20: RIV | B20: 2020 | C20: 0.215 | D20: 0.186 | E20: 0.246 | F20: 240
A21: RIV | B21: 2021 | C21: 0.205 | D21: 0.202 | E21: 0.239 | F21: 273
A22: RIV | B22: 2022 | C22: 0.205 | D22: 0.165 | E22: 0.228 | F22: 322
A23: SBR | B23: 2016 | F23: 221
A24: SBR | B24: 2017 | C24: 0.204 | D24: 0.18 | E24: 0.233 | F24: 323 | G24: No county, use state
A25: SBR | B25: 2018 | C25: 0.184 | D25: 0.191 | E25: 0.217 | F25: 261
A26: SBR | B26: 2019 | C26: 0.205 | D26: 0.15 | E26: 0.223 | F26: 248
A27: SBR | B27: 2020 | C27: 0.215 | D27: 0.186 | E27: 0.246 | F27: 268
A28: SBR | B28: 2021 | C28: 0.205 | D28: 0.202 | E28: 0.239 | F28: 300
A29: SBR | B29: 2022 | C29: 0.205 | D29: 0.165 | E29: 0.228 | F29: 293
A30: LOR | B30: 2016
A31: LOR | B31: 2017 | C31: =C3*F3/SUM(F3,F10,F17,F24)+C10*F10/SUM(F3,F10,F17,F24)+C17*F17/SUM(F3,F10,F17,F24)+C24*F24/SUM(F3,F10,F17,F24) -> 0.204 | D31: =D3*F3/SUM(F3,F10,F17,F24)+D10*F10/SUM(F3,F10,F17,F24)+D17*F17/SUM(F3,F10,F17,F24)+D24*F24/SUM(F3,F10,F17,F24) -> 0.18 | E31: =E3*F3/SUM(F3,F10,F17,F24)+E10*F10/SUM(F3,F10,F17,F24)+E17*F17/SUM(F3,F10,F17,F24)+E24*F24/SUM(F3,F10,F17,F24) -> 0.233
A32: LOR | B32: 2018 | C32: =C4*F4/SUM(F4,F11,F18,F25)+C11*F11/SUM(F4,F11,F18,F25)+C18*F18/SUM(F4,F11,F18,F25)+C25*F25/SUM(F4,F11,F18,F25) -> 0.14504333 | D32: =D4*F4/SUM(F4,F11,F18,F25)+D11*F11/SUM(F4,F11,F18,F25)+D18*F18/SUM(F4,F11,F18,F25)+D25*F25/SUM(F4,F11,F18,F25) -> 0.16297853 | E32: =E4*F4/SUM(F4,F11,F18,F25)+E11*F11/SUM(F4,F11,F18,F25)+E18*F18/SUM(F4,F11,F18,F25)+E25*F25/SUM(F4,F11,F18,F25) -> 0.18146058
A33: LOR | B33: 2019 | C33: =C5*F5/SUM(F5,F12,F19,F26)+C12*F12/SUM(F5,F12,F19,F26)+C19*F19/SUM(F5,F12,F19,F26)+C26*F26/SUM(F5,F12,F19,F26) -> 0.16460647 | D33: =D5*F5/SUM(F5,F12,F19,F26)+D12*F12/SUM(F5,F12,F19,F26)+D19*F19/SUM(F5,F12,F19,F26)+D26*F26/SUM(F5,F12,F19,F26) -> 0.1133351 | E33: =E5*F5/SUM(F5,F12,F19,F26)+E12*F12/SUM(F5,F12,F19,F26)+E19*F19/SUM(F5,F12,F19,F26)+E26*F26/SUM(F5,F12,F19,F26) -> 0.19814244
A34: LOR | B34: 2020 | C34: =C6*F6/SUM(F6,F13,F20,F27)+C13*F13/SUM(F6,F13,F20,F27)+C20*F20/SUM(F6,F13,F20,F27)+C27*F27/SUM(F6,F13,F20,F27) -> 0.18108288 | D34: =D6*F6/SUM(F6,F13,F20,F27)+D13*F13/SUM(F6,F13,F20,F27)+D20*F20/SUM(F6,F13,F20,F27)+D27*F27/SUM(F6,F13,F20,F27) -> 0.16512793 | E34: =E6*F6/SUM(F6,F13,F20,F27)+E13*F13/SUM(F6,F13,F20,F27)+E20*F20/SUM(F6,F13,F20,F27)+E27*F27/SUM(F6,F13,F20,F27) -> 0.24208649
A35: LOR | B35: 2021 | C35: =C7*F7/SUM(F7,F14,F21,F28)+C14*F14/SUM(F7,F14,F21,F28)+C21*F21/SUM(F7,F14,F21,F28)+C28*F28/SUM(F7,F14,F21,F28) -> 0.16873154 | D35: =D7*F7/SUM(F7,F14,F21,F28)+D14*F14/SUM(F7,F14,F21,F28)+D21*F21/SUM(F7,F14,F21,F28)+D28*F28/SUM(F7,F14,F21,F28) -> 0.18386577 | E35: =E7*F7/SUM(F7,F14,F21,F28)+E14*F14/SUM(F7,F14,F21,F28)+E21*F21/SUM(F7,F14,F21,F28)+E28*F28/SUM(F7,F14,F21,F28) -> 0.21633221
A36: LOR | B36: 2022 | C36: =C8*F8/SUM(F8,F15,F22,F29)+C15*F15/SUM(F8,F15,F22,F29)+C22*F22/SUM(F8,F15,F22,F29)+C29*F29/SUM(F8,F15,F22,F29) -> 0.205 | D36: =D8*F8/SUM(F8,F15,F22,F29)+D15*F15/SUM(F8,F15,F22,F29)+D22*F22/SUM(F8,F15,F22,F29)+D29*F29/SUM(F8,F15,F22,F29) -> 0.165 | E36: =E8*F8/SUM(F8,F15,F22,F29)+E15*F15/SUM(F8,F15,F22,F29)+E22*F22/SUM(F8,F15,F22,F29)+E29*F29/SUM(F8,F15,F22,F29) -> 0.228
A37: BRO | B37: 2016 | F37: 639
A38: BRO | B38: 2017 | C38: =AVERAGE(C39:C43) -> 0.1852 | D38: =AVERAGE(D39:D43) -> 0.2384 | E38: =AVERAGE(E39:E43) -> 0.1864 | F38: 622
A39: BRO | B39: 2018 | C39: 0.211 | D39: 0.226 | E39: 0.201 | F39: 544
A40: BRO | B40: 2019 | C40: 0.179 | D40: 0.257 | E40: 0.168 | F40: 519
...

Sheet obs.inc.all
A1: city | B1: year | C1: value | D1: low | E1: high
A2: LA1 | B2: 2017 | C2: 2061.3254 | D2: 1855.1929 | E2: 2226.2315
A3: LA1 | B3: 2018 | C3: 2061.3254 | D3: 1855.1929 | E3: 2226.2315
A4: LA1 | B4: 2019 | C4: 2061.3254 | D4: 1855.1929 | E4: 2226.2315
A5: LA1 | B5: 2020 | C5: 1822.7708 | D5: 1599.5744 | E5: 2008.7678
A6: LA1 | B6: 2021 | C6: 2136.314 | D6: 1854.1594 | E6: 2418.4687
A7: LA1 | B7: 2022 | C7: 2030.584 | D7: 1712.061 | E7: 2349.107
A8: NYC1 | B8: 2017 | C8: 1214.3975 | D8: 982.61578 | E8: 1446.1792
A9: NYC1 | B9: 2018 | C9: 1214.3975 | D9: 982.61578 | E9: 1446.1792
A10: NYC1 | B10: 2019 | C10: 1214.3975 | D10: =C10-(C16-D16)/C16*C10 -> 982.61578 | E10: =C10+(C16-D16)/C16*C10 -> 1446.1792
A11: NYC1 | B11: 2020 | C11: 1170.1379 | D11: =C11-(C17-D17)/C17*C11 -> 994.27546 | E11: =C11+(C17-D17)/C17*C11 -> 1346.0004
A12: NYC1 | B12: 2021 | C12: 1207.7397 | D12: =C12-(C18-D18)/C18*C12 -> 1020.6251 | E12: =C12+(C18-D18)/C18*C12 -> 1394.8543
A13: NYC1 | B13: 2022 | C13: 1434.7719 | D13: =C13-(C19-D19)/C19*C13 -> 1184.3636 | E13: =C13+(C19-D19)/C19*C13 -> 1685.1802
A14: MIA1 | B14: 2017 | C14: 2101 | D14: 1700 | E14: 2500
A15: MIA1 | B15: 2018 | C15: 2101 | D15: 1700 | E15: 2500
A16: MIA1 | B16: 2019 | C16: 2101 | D16: 1700 | E16: 2500
A17: MIA1 | B17: 2020 | C17: 1883 | D17: 1600 | E17: 2250
A18: MIA1 | B18: 2021 | C18: 1775 | D18: 1500 | E18: 2100
A19: MIA1 | B19: 2022 | C19: 1696 | D19: 1400 | E19: 2100
A20: SFA
A21: SFA
A22: SFA
A23: SFA
A24: SFA
A25: SFA
A26: LOR
A27: LOR | B27: 2017
A28: LOR | B28: 2018
A29: LOR | B29: 2019
A30: LOR | B30: 2020
A31: LOR | B31: 2021
A32: SAC | B32: 2022
A33: SAC
A34: SAC
A35: SAC
A36: SAC
A37: SAC
A38: SDI
A39: SDI
A40: SDI
...

Sheet obs.inc.msm
A1: city | B1: year | C1: value | D1: low | E1: high
A2: LA1 | B2: 2017 | C2: 1732.8778 | D2: 1559.59 | E2: 1871.508
A3: LA1 | B3: 2018 | C3: 1732.8778 | D3: 1559.59 | E3: 1871.508
A4: LA1 | B4: 2019 | C4: 1732.8778 | D4: 1559.59 | E4: 1871.508
A5: LA1 | B5: 2020 | C5: 1497.1297 | D5: 1313.8077 | E5: 1649.8981
A6: LA1 | B6: 2021 | C6: 1789.2264 | D6: 1552.9135 | E6: 2025.5394
A7: LA1 | B7: 2022 | C7: 1706.8968 | D7: 1439.1483 | E7: 1974.6454
A8: NYC1 | B8: 2017 | C8: 728.84556 | D8: 572.76665 | E8: 884.92447
A9: NYC1 | B9: 2018 | C9: 728.84556 | D9: 572.76665 | E9: 884.92447
A10: NYC1 | B10: 2019 | C10: 728.84556 | D10: =C10-(C16-D16)/C16*C10 -> 572.76665 | E10: =C10+(C16-D16)/C16*C10 -> 884.92447
A11: NYC1 | B11: 2020 | C11: 740.39701 | D11: =C11-(C17-D17)/C17*C11 -> 594.59257 | E11: =C11+(C17-D17)/C17*C11 -> 886.20145
A12: NYC1 | B12: 2021 | C12: 830.1312 | D12: =C12-(C18-D18)/C18*C12 -> 688.2847 | E12: =C12+(C18-D18)/C18*C12 -> 971.9777
A13: NYC1 | B13: 2022 | C13: 991.12532 | D13: =C13-(C19-D19)/C19*C13 -> 731.03187 | E13: =C13+(C19-D19)/C19*C13 -> 1251.2188
A14: MIA1 | B14: 2017 | C14: 1527 | D14: 1200 | E14: 1750
A15: MIA1 | B15: 2018 | C15: 1527 | D15: 1200 | E15: 1750
A16: MIA1 | B16: 2019 | C16: 1527 | D16: 1200 | E16: 1750
A17: MIA1 | B17: 2020 | C17: 1432 | D17: 1150 | E17: 1650
A18: MIA1 | B18: 2021 | C18: 1387 | D18: 1150 | E18: 1625
A19: MIA1 | B19: 2022 | C19: 1288 | D19: 950 | E19: 1625
A20: SFA
A21: SFA
A22: SFA
A23: SFA
A24: SFA
A25: SFA
A26: LOR
A27: LOR | B27: 2017
A28: LOR | B28: 2018
A29: LOR | B29: 2019
A30: LOR | B30: 2020
A31: LOR | B31: 2021
A32: SAC | B32: 2022
A33: SAC
A34: SAC
A35: SAC
A36: SAC
A37: SAC
A38: SDI
A39: SDI
A40: SDI
...

Sheet notes
P1: Code
A2: all data from atlas plus (new diagnoses, hiv perevalence, viral suppression, mortality) | P2: MAR
A3: late diagnoses is collected thorugh local surveillance reports… | P3: SFA
A4: age assumption <15 is 0 in example tab (atlas plus bin is 13-24) | P4: LOR
A5: 13-24 included in 15-64 | P5: SAC
A6: suppressed data assume = 4 | P6: SDI
A7: if data is suppressed, add up risk/age/sex and compare to total. | P7: DUV
A8: From total, adjust risk/sex/age in suppressed cells to fit total | P8: TAM
A9: for race consider that "other races" are included in total through white (see yellow box below) | P9: BMP
P10: ORF
A11: Steps for transformation (example tab) | P11: ATL
A12: step 1 input raw data | P12: COO
A13: make sure total from "example step 1 15-64" adds up to summed up data from step 4 | P13: MIN
A14: in the actual triangulation, make sure risk columns add up to the sum of race columns | P14: EBR
A15: make sure that sex risk groups adds up to the 15-64 raw data in example step 1 | P15: ORL
P16: BAL
P17: SUF
A18: VERY IMPORTANT | P18: WAY
A19: the example sheet has formulas in step 1 to calculate female, heterosexual and white to fit the model. DO NOT PUT THE RAW DATA IN THOSE CELLS | P19: CLA
A20: adjust female count = total - male | P20: NYC
A21: het adjust formula = total - msm - mwid - pwid | P21: NJE
A22: adjusted white = total - black - hispanic | P22: MEC
A23: total = sum of less than 15, 15-64, and 65+ | P23: CUY
P24: FRA
P25: HAM
P26: PHI
A27: the example sheet has formulas in step 1 to calculate female, heterosexual and white to fit the model | P27: SHE
A28: DO NOT PUT THE RAW DATA IN THOSE CELLS | P28: BEX
P29: DFW
A30: •For jurisdictions where multiple counties are added (e.g. NYC has 5 boroughs included) add all the data in step 1 (from raw data) | P30: HAR
P31: TRV
A32: For new diagnoses: Once the data is transformed and is being copy-pasted into the finalized table, make sure the sum of race groups equal the sum of risk groups in the final table. As the data transformation final counts are rounded, adjustments may need to be made if they are not equal. Make adjustments in the MWID columns. Usually these adjustments are minor (+ - 5). Adjustments can happen in either MWID column, and follows an overall trend. You can “eyeball it” for the adjustments. In the model, MWID counts are added into MSM (the largest risk group), so minor manual adjustments are not a big issue as long as the sum of race groups = sum of risk groups. | P32: KIN
P33: DCM
